Workbook

Sheet Dashboard
A1: Dashboard — LH₂ vs Ammonia Shipping
A2: Headline read at the current Inputs. Kakinada, India → Hamburg, Germany.
A4: WINNER ON THROUGHPUT | B4: LH₂ ANNUAL DELIVERY | C4: NH₃ ANNUAL DELIVERY | D4: NH₃ SHIPS PER LH₂ SHIP
A5: =IF('Voyage Model'!$C$15>'Voyage Model'!$D$15,"LH₂","NH₃") -> LH₂ | B5: ='Voyage Model'!$C$15 -> 55.24393 | C5: ='Voyage Model'!$D$15 -> 12.2496 | D5: ='Voyage Model'!$C$15/'Voyage Model'!$D$15 -> 4.5098559
A6: Annual H2-equivalent delivered per vessel, ktpa (see the two tiles at right). | B6: See Voyage Model row 16 for the fleet size this implies. | C6: See Voyage Model row 16 for the fleet size this implies. | D6: At the currently selected capacities for both carriers.
A8: BOIL-OFF COVERS PROPULSION DEMAND | B8: LH₂ COST PER KG H₂ (ACTIVE MODE) | C8: NH₃ COST PER KG H₂ (ACTIVE MODE) | D8: CHEAPER CARRIER (ACTIVE MODE)
A9: ='Voyage Model'!$C$24 -> 2.5760269 | B9: ='Voyage Model'!$C$42 -> 0.26502143 | C9: ='Voyage Model'!$D$42 -> 0.0090088785 | D9: =IF('Voyage Model'!$C$42<'Voyage Model'!$D$42,"LH₂","NH₃") -> NH₃
A10: >100% = surplus is wasted; <100% = ship still buys top-up VLSFO. | B10: Active mode set on the Inputs sheet. | C10: Active mode set on the Inputs sheet. | D10: Boil-off cost per kg H2 delivered, active mode.
A12: BREAKEVEN LH₂ BOIL-OFF (THROUGHPUT) | B12: BREAKEVEN LH₂ BOIL-OFF (FUEL COVER) | C12: BREAKEVEN H₂ VALUE | D12: BREAKEVEN NH₃ CAPACITY
A13: ='Voyage Model'!$B$46 -> 0.051122998 | B13: ='Voyage Model'!$B$47 -> 0.00076273733 | C13: ='Voyage Model'!$B$51 -> 0.84160472 | D13: ='Voyage Model'!$B$50 -> 108236.54
A14: Above this LH2 BOR, NH3 delivers more annual H2-eq per vessel. | B14: Above this LH2 BOR, boil-off exceeds propulsion demand and is wasted. | C14: Above this hydrogen value, ammonia is cheaper on the active cost basis. | D14: NH3 capacity needed to match one LH2 ship's annual throughput.
A17: OPEN GAPS — nothing here is fabricated; see Inputs sheet Tag column
A18: • LH₂ voyage boil-off rate: KHI never disclosed one — the single biggest lever in this workbook.
A19: • LH₂ propulsion duty (25 t/day): carried over from the ammonia vessel; a 160,000 m³ hull at ~16 kn plausibly burns several times this. See the Suggested Duty cells on Inputs.
A20: • Every NH₃ vessel figure (speed, capacity, port time, BOR, reliquefaction energy) is user-stated or estimated, pending the internal Gentari NH3 dataset (decision D4).
A21: • Hydrogen value and VLSFO price are set by you — neither is logged in the repository; the model reports breakeven prices rather than asserting one.
A22: • Corridor distance is a first-principles great-circle estimate, not an AIS/route-planner figure.

Sheet Inputs
A1: LH₂ vs Ammonia — Shipping Inputs
A2: Edit any blue cell — every sheet, table and chart in this workbook recomputes live. Corridor: Kakinada, India → Hamburg, Germany. Font: Arial throughout.
A4: Parameter | B4: Value | C4: Unit | D4: Tag | E4: Note / source
A5: CORRIDOR — Kakinada, India → Hamburg, Germany
A6: One-way distance | B6: 21200 | C6: km | D6: ESTIMATE | E6: First-principles great-circle waypoint sum (distance-calculator sites are egress-blocked from this environment). Suez route ≈10,260 km; Cape of Good Hope route (primary, current Red Sea rerouting reality) ≈21,200 km. See data/routes/kakinada-hamburg.csv.
A8: LH₂ VESSEL
A9: Capacity (choose 40,000 or 160,000) | B9: 160000 | C9: m³ | D9: CITED | E9: KHI-disclosed. 40,000 m³ = vessel under construction (reply Q29); 160,000 m³ = commercial-scale target (cost-basis slide).
A10: Cargo density | B10: 70.8 | C10: kg/m³ | D10: needs-source | E10: LH2 at NBP; data/properties/lh2-properties.csv, pending NIST/CODATA citation.
A11: Fill fraction | B11: 0.98 | C11: % | D11: ASSUMPTION | E11: Ullage / ship-fill-limit placeholder, not KHI-specific.
A12: Service speed | B12: 29.6 | C12: km/h | D12: CITED | E12: ≈16 kn; kawasaki-2026-supplemental, given for the 160,000 m³ commercial vessel and reused for the 40,000 m³ hull.
A13: Port days per call | B13: 1.25 | C13: day | D13: CITED | E13: Midpoint of KHI's disclosed 1–1.5 day range (reply Q27).
A14: Voyage boil-off rate | B14: 0.002 | C14: %/day | D14: ESTIMATE | E14: KHI never disclosed a standalone voyage BOR. The single biggest lever in this workbook. Literature (RSER 2026, unpromoted) suggests ~3.44%/day for a comparable vessel class.
A15: Propulsion fuel duty (VLSFO) | B15: 25 | C15: t/day | D15: ASSUMPTION | E15: Carried over from the ammonia vessel's stated duty so both ships share one basis — NOT a disclosed figure for either LH2 hull. See suggested-duty cell below.
A17: NH₃ VESSEL (fully refrigerated, ~-33°C)
A18: Capacity (choose 24k / 40k / 60k / 90k) | B18: 24000 | C18: m³ | D18: ASSUMPTION | E18: 24,000 m³ = originally specified vessel; 40k/60k/90k = mid-size / large / VLGC-scale gas-carrier size bands (general industry classes, not repository figures). Largest ammonia carriers in service are ~87,000 m³.
A19: Cargo density | B19: 682 | C19: kg/m³ | D19: ESTIMATE | E19: Standard published value for refrigerated liquid ammonia; no primary citation logged yet.
A20: Fill fraction | B20: 0.98 | C20: % | D20: ASSUMPTION | E20: Matched to the LH2 side for comparability.
A21: Service speed | B21: 13 | C21: knot | D21: ASSUMPTION | E21: User-specified. Converted to km/h below.
A22: → converted speed | B22: =$B$21*1.852 -> 24.076 | C22: km/h | E22: 13 kn × 1.852 = 24.076 km/h
A23: Port days per call | B23: 1.5 | C23: day | D23: ASSUMPTION | E23: Matched to the LH2 carrier's disclosed range for comparability.
A24: Voyage boil-off rate | B24: 0.0015 | C24: %/day | D24: ASSUMPTION | E24: User selected the 0.10–0.20%/day range; midpoint used as the point default.
A25: Propulsion fuel duty (VLSFO) | B25: 25 | C25: t/day | D25: ASSUMPTION | E25: User-specified.
A26: Re-liquefaction energy | B26: 0.25 | C26: kWh/kg BOG | D26: ESTIMATE | E26: Placeholder — no NH3 dataset yet (decision D4).
A27: Reliquefaction genset efficiency | B27: 0.45 | C27: % | D27: ASSUMPTION | E27: Typical medium-speed marine genset efficiency; not vessel-specific.
A29: SHARED ASSUMPTIONS
A30: Fleet availability | B30: 0.9 | C30: % | D30: ASSUMPTION | E30: Dry-docking / maintenance / weather margin.
A31: Annual H₂-equivalent demand | B31: 100 | C31: ktpa | D31: ASSUMPTION | E31: Study basis — quantity handed to the ships, not upstream production.
A32: NH₃ : H₂ stoichiometric ratio | B32: 5.632 | C32: kg/kg | D32: ASSUMPTION | E32: First-principles: N₂ + 3H₂ → 2NH₃.
A33: VLSFO lower heating value | B33: 40.2 | C33: MJ/kg | D33: ESTIMATE | E33: Marine convention for (very-low-sulphur) fuel oil.
A34: H₂ lower heating value | B34: 120 | C34: MJ/kg | D34: needs-source | E34: data/properties/lh2-properties.csv, pending NIST/ISO citation.
A35: BOG vs oil engine efficiency ratio | B35: 1 | C35: kg/kg | D35: ASSUMPTION | E35: Thermal efficiency burning cargo boil-off vs burning liquid bunker fuel in the same engine. 1.0 = identical.
A36: Vented H₂ warming potential (GWP100) | B36: 11.6 | C36: kgCO2e/kg | D36: ESTIMATE | E36: Wide published uncertainty band, no primary citation logged. Applies only if disposal below = Vented — a gas combustion unit burns it to water instead.
A38: PRICES & MODE (set by you — nothing here is a repository default)
A39: Hydrogen value | B39: 5 | C39: USD/kg | D39: needs-source | E39: Not logged anywhere in the repository. The model reports a breakeven price rather than asserting one.
A40: VLSFO price | B40: 600 | C40: USD/t | D40: needs-source | E40: Not logged in the repository.
A41: Cost basis mode | B41: Boil-off only | C41: choice | D41: CHOICE | E41: "Boil-off only" charges each carrier just what its boil-off costs. "Full leg fuel bill" adds the whole propulsion duty each ship buys — kept because the two laden legs differ in length, so that term does not cleanly cancel.
A42: Surplus boil-off disposal | B42: Vented | C42: choice | D42: CHOICE | E42: Boil-off above the engine's demand cannot be used for propulsion regardless. "GCU burned" oxidises it to water (KHI reply Q26) instead of releasing it — the hydrogen is lost from cargo either way; only the CO2e line changes.
A43: Boil-off fate basis (Sens - Boiloff sheet) | B43: Per laden leg | C43: choice | D43: CHOICE | E43: Switches the "fate of the boil-off" table/chart between totals for the whole one-way route and a daily rate.
A44: Duty scaling exponent (Decision Map sheet) | B44: 0.667 | C44: exponent | D44: ASSUMPTION | E44: How LH2 propulsion duty scales with hull size when the Decision Map sweeps capacity, anchored on the 24,000 m³ / 25 t/day pair. 0 = duty fixed; 0.667 = resistance ≈ wetted area (default); 1 = duty ∝ cargo (coverage constant, size drops out). No power curve is held for any vessel.
A46: SUGGESTED DUTY (informational only — not applied automatically)
...

Sheet Voyage Model
A1: Voyage Model
A2: One voyage, both carriers, at the current Inputs. Every downstream sheet reads from here or recomputes the same formulas at swept values.
A4: Metric | B4: Unit | C4: LH₂ carrier | D4: NH₃ carrier | E4: Note
A5: VOYAGE & THROUGHPUT
A6: One-way transit | B6: day | C6: =Inputs!$B$6/Inputs!$B$12/24 -> 29.842342 | D6: =Inputs!$B$6/Inputs!$B$22/24 -> 36.689373
A7: Round-trip cycle | B7: day | C7: =2*$C$6+2*Inputs!$B$13 -> 62.184685 | D7: =2*$D$6+2*Inputs!$B$23 -> 76.378745
A8: Cargo loaded per voyage | B8: kg | C8: =Inputs!$B$9*Inputs!$B$10*Inputs!$B$11 -> 11101440 | D8: =Inputs!$B$18*Inputs!$B$19*Inputs!$B$20 -> 16040640
A9: Boil-off fraction (compounding, laden leg) | B9: % | C9: =1-(1-Inputs!$B$14)^$C$6 -> 0.057994767 | D9: =1-(1-Inputs!$B$24)^$D$6 -> 0.053586191 | E9: Compounding daily loss over the one-way laden leg only (matches src/lh2/chain_energy.py's voyage_days() convention).
A10: Cargo mass-loss fraction | B10: % | C10: =$C$9 -> 0.057994767 | D10: =0 -> 0 | E10: LH2 burns boil-off as fuel → cargo mass lost = boil-off fraction. NH3 re-liquefies on board → no mass loss (energy cost instead, costed below).
A11: Delivered cargo per voyage | B11: kg | C11: =$C$8*(1-$C$10) -> 10457615 | D11: =$D$8*(1-$D$10) -> 16040640
A12: Trips per vessel-year | B12: trips/y | C12: =365/$C$7*Inputs!$B$30 -> 5.2826512 | D12: =365/$D$7*Inputs!$B$30 -> 4.3009348
A13: Annual delivered cargo per vessel | B13: kg/y | C13: =$C$11*$C$12 -> 55243930 | D13: =$D$11*$D$12 -> 68989746
A14: Annual delivered H₂-equivalent per vessel | B14: kg/y | C14: =$C$13 -> 55243930 | D14: =$D$13/Inputs!$B$32 -> 12249600
A15: Annual delivered H₂-equivalent per vessel | B15: ktpa | C15: =$C$14/1000000 -> 55.24393 | D15: =$D$14/1000000 -> 12.2496
A16: Fleet size for the stated annual demand | B16: vessels | C16: =CEILING(Inputs!$B$31*1000000/$C$13,1) -> 2 | D16: =CEILING(Inputs!$B$31*1000000*Inputs!$B$32/$D$13,1) -> 9 | E16: Ships must LOAD enough cargo, net of voyage loss, to meet the delivered H2-equivalent demand.
A18: BUNKER FUEL & BOIL-OFF BALANCE
A19: Propulsion energy demand (laden leg) | B19: MJ | C19: =Inputs!$B$15*1000*$C$6*Inputs!$B$33 -> 29991554 | D19: =Inputs!$B$25*1000*$D$6*Inputs!$B$33 -> 36872819
A20: Boil-off generated (laden leg) | B20: kg | C20: =$C$8*$C$9 -> 643825.42 | D20: =$D$8*$D$9 -> 859556.8
A21: Boil-off energy available to burn | B21: MJ | C21: =$C$20*Inputs!$B$34*Inputs!$B$35 -> 77259051 | D21: =0 -> 0 | E21: NH3 does not burn its boil-off for propulsion — it re-liquefies it (see reliquefaction fuel row below).
A22: — useful (displaces VLSFO) | B22: MJ | C22: =MIN($C$21,$C$19) -> 29991554 | D22: =0 -> 0
A23: — surplus (cannot be used for propulsion) | B23: MJ | C23: =MAX(0,$C$21-$C$19) -> 47267497 | D23: =0 -> 0
A24: Boil-off covers this share of propulsion demand | B24: % | C24: =IF($C$19=0,0,$C$21/$C$19) -> 2.5760269 | D24: =0 -> 0 | E24: Above 100%, the surplus is wasted. Below 100%, top-up VLSFO is still bought.
A25: — useful boil-off mass | B25: kg | C25: =IF(Inputs!$B$34*Inputs!$B$35=0,0,$C$22/(Inputs!$B$34*Inputs!$B$35)) -> 249929.62 | D25: =0 -> 0
A26: — surplus boil-off mass | B26: kg | C26: =IF(Inputs!$B$34*Inputs!$B$35=0,0,$C$23/(Inputs!$B$34*Inputs!$B$35)) -> 393895.81 | D26: =0 -> 0
A27: Top-up VLSFO bought | B27: t | C27: =MAX(0,$C$19-$C$21)/Inputs!$B$33/1000 -> 0 | D27: =Inputs!$B$25*$D$6 -> 917.23431 | E27: NH3 always buys its full propulsion duty in bunker fuel — its boil-off is re-liquefied, never burned for propulsion.
A28: VLSFO displaced by boil-off | B28: t | C28: =$C$22/Inputs!$B$33/1000 -> 746.05856 | D28: =0 -> 0
A29: Reliquefaction electricity required | B29: kWh | C29: =0 -> 0 | D29: =$D$20*Inputs!$B$26 -> 214889.2
A30: Reliquefaction VLSFO (via genset) | B30: t | C30: =0 -> 0 | D30: =$D$29*3.6/(Inputs!$B$33*Inputs!$B$27)/1000 -> 42.76402
A31: Total VLSFO purchased | B31: t | C31: =$C$27 -> 0 | D31: =$D$27+$D$30 -> 959.99833
A32: Cargo mass lost to boil-off | B32: kg | C32: =$C$20 -> 643825.42 | D32: =0 -> 0 | E32: 0 for NH3: re-liquefaction conserves cargo mass.
A33: Delivered H₂-equivalent, this voyage | B33: kg | C33: =$C$11 -> 10457615 | D33: =$D$11/Inputs!$B$32 -> 2848125
A34: CO₂e if surplus is vented | B34: kg CO2e | C34: =IF(Inputs!$B$42="Vented",$C$26*Inputs!$B$36,0) -> 4569191.4 | D34: =0 -> 0 | E34: 0 whenever disposal = "GCU burned": the gas combustion unit oxidises surplus H2 to water (KHI reply Q26); the hydrogen is still lost from cargo either way.
A36: COST PER KG H₂ DELIVERED
A37: Hydrogen given up, priced as fuel | B37: USD | C37: =$C$32*Inputs!$B$39 -> 3219127.1 | D37: =0 -> 0
A38: Fuel cost — boil-off only basis | B38: USD | C38: =($C$30-$C$28)*Inputs!$B$40 -> -447635.14 | D38: =($D$30-$D$28)*Inputs!$B$40 -> 25658.412 | E38: LH2: negative (a credit) — the VLSFO its own boil-off displaced. NH3: the genset fuel to re-liquefy.
A39: Fuel cost — full leg fuel bill basis | B39: USD | C39: =$C$31*Inputs!$B$40 -> 0 | D39: =$D$31*Inputs!$B$40 -> 575999
A40: Fuel cost — ACTIVE (per Inputs mode) | B40: USD | C40: =IF(Inputs!$B$41="Boil-off only",$C$38,$C$39) -> -447635.14 | D40: =IF(Inputs!$B$41="Boil-off only",$D$38,$D$39) -> 25658.412
A41: Total cost, active mode | B41: USD | C41: =$C$37+$C$40 -> 2771492 | D41: =$D$37+$D$40 -> 25658.412
A42: Cost per kg H₂ delivered, active mode | B42: USD/kg | C42: =$C$41/$C$33 -> 0.26502143 | D42: =$D$41/$D$33 -> 0.0090088785
A44: BREAKEVENS (closed-form; all relationships here invert algebraically)
...

Sheet Sens - Distance
A1: Sensitivity — Distance
A2: Annual H₂-equivalent delivered per vessel against one-way distance, at the current LH2/NH3 vessel specs. Distance alone does not flip the winner in the realistic range.
A4: Distance (km) | B4: LH₂ (ktpa/vessel) | C4: NH₃ (ktpa/vessel) | D4: LH₂ fleet size | E4: NH₃ fleet size
A5: 1000 | B5: =('Voyage Model'!$C$8*(1-H5)*(365/F5*Inputs!$B$30))/1000000 -> 684.16642 | C5: =('Voyage Model'!$D$8*(365/G5*Inputs!$B$30)/Inputs!$B$32)/1000000 -> 144.80285 | D5: =CEILING(Inputs!$B$31*1000000/('Voyage Model'!$C$8*(1-H5)*(365/F5*Inputs!$B$30)),1) -> 1 | E5: =CEILING(Inputs!$B$31*1000000*Inputs!$B$32/('Voyage Model'!$D$8*(365/G5*Inputs!$B$30)/Inputs!$B$32),1) -> 4 | F5: =2*(A5/Inputs!$B$12/24)+2*Inputs!$B$13 -> 5.3153153 | G5: =2*(A5/Inputs!$B$22/24)+2*Inputs!$B$23 -> 6.4612616 | H5: =1-(1-Inputs!$B$14)^(A5/Inputs!$B$12/24) -> 0.0028141672
A6: 2000 | B6: =('Voyage Model'!$C$8*(1-H6)*(365/F6*Inputs!$B$30))/1000000 -> 446.00801 | C6: =('Voyage Model'!$D$8*(365/G6*Inputs!$B$30)/Inputs!$B$32)/1000000 -> 94.291447 | D6: =CEILING(Inputs!$B$31*1000000/('Voyage Model'!$C$8*(1-H6)*(365/F6*Inputs!$B$30)),1) -> 1 | E6: =CEILING(Inputs!$B$31*1000000*Inputs!$B$32/('Voyage Model'!$D$8*(365/G6*Inputs!$B$30)/Inputs!$B$32),1) -> 6 | F6: =2*(A6/Inputs!$B$12/24)+2*Inputs!$B$13 -> 8.1306306 | G6: =2*(A6/Inputs!$B$22/24)+2*Inputs!$B$23 -> 9.9225231 | H6: =1-(1-Inputs!$B$14)^(A6/Inputs!$B$12/24) -> 0.0056204148
A7: 3000 | B7: =('Voyage Model'!$C$8*(1-H7)*(365/F7*Inputs!$B$30))/1000000 -> 330.3617 | C7: =('Voyage Model'!$D$8*(365/G7*Inputs!$B$30)/Inputs!$B$32)/1000000 -> 69.906165 | D7: =CEILING(Inputs!$B$31*1000000/('Voyage Model'!$C$8*(1-H7)*(365/F7*Inputs!$B$30)),1) -> 1 | E7: =CEILING(Inputs!$B$31*1000000*Inputs!$B$32/('Voyage Model'!$D$8*(365/G7*Inputs!$B$30)/Inputs!$B$32),1) -> 9 | F7: =2*(A7/Inputs!$B$12/24)+2*Inputs!$B$13 -> 10.945946 | G7: =2*(A7/Inputs!$B$22/24)+2*Inputs!$B$23 -> 13.383785 | H7: =1-(1-Inputs!$B$14)^(A7/Inputs!$B$12/24) -> 0.0084187652
A8: 4000 | B8: =('Voyage Model'!$C$8*(1-H8)*(365/F8*Inputs!$B$30))/1000000 -> 262.03593 | C8: =('Voyage Model'!$D$8*(365/G8*Inputs!$B$30)/Inputs!$B$32)/1000000 -> 55.542089 | D8: =CEILING(Inputs!$B$31*1000000/('Voyage Model'!$C$8*(1-H8)*(365/F8*Inputs!$B$30)),1) -> 1 | E8: =CEILING(Inputs!$B$31*1000000*Inputs!$B$32/('Voyage Model'!$D$8*(365/G8*Inputs!$B$30)/Inputs!$B$32),1) -> 11 | F8: =2*(A8/Inputs!$B$12/24)+2*Inputs!$B$13 -> 13.761261 | G8: =2*(A8/Inputs!$B$22/24)+2*Inputs!$B$23 -> 16.845046 | H8: =1-(1-Inputs!$B$14)^(A8/Inputs!$B$12/24) -> 0.011209241
A9: 5000 | B9: =('Voyage Model'!$C$8*(1-H9)*(365/F9*Inputs!$B$30))/1000000 -> 216.92037 | C9: =('Voyage Model'!$D$8*(365/G9*Inputs!$B$30)/Inputs!$B$32)/1000000 -> 46.0748 | D9: =CEILING(Inputs!$B$31*1000000/('Voyage Model'!$C$8*(1-H9)*(365/F9*Inputs!$B$30)),1) -> 1 | E9: =CEILING(Inputs!$B$31*1000000*Inputs!$B$32/('Voyage Model'!$D$8*(365/G9*Inputs!$B$30)/Inputs!$B$32),1) -> 13 | F9: =2*(A9/Inputs!$B$12/24)+2*Inputs!$B$13 -> 16.576577 | G9: =2*(A9/Inputs!$B$22/24)+2*Inputs!$B$23 -> 20.306308 | H9: =1-(1-Inputs!$B$14)^(A9/Inputs!$B$12/24) -> 0.013991863
A10: 6000 | B10: =('Voyage Model'!$C$8*(1-H10)*(365/F10*Inputs!$B$30))/1000000 -> 184.90604 | C10: =('Voyage Model'!$D$8*(365/G10*Inputs!$B$30)/Inputs!$B$32)/1000000 -> 39.364945 | D10: =CEILING(Inputs!$B$31*1000000/('Voyage Model'!$C$8*(1-H10)*(365/F10*Inputs!$B$30)),1) -> 1 | E10: =CEILING(Inputs!$B$31*1000000*Inputs!$B$32/('Voyage Model'!$D$8*(365/G10*Inputs!$B$30)/Inputs!$B$32),1) -> 15 | F10: =2*(A10/Inputs!$B$12/24)+2*Inputs!$B$13 -> 19.391892 | G10: =2*(A10/Inputs!$B$22/24)+2*Inputs!$B$23 -> 23.767569 | H10: =1-(1-Inputs!$B$14)^(A10/Inputs!$B$12/24) -> 0.016766655
A11: 7000 | B11: =('Voyage Model'!$C$8*(1-H11)*(365/F11*Inputs!$B$30))/1000000 -> 161.01022 | C11: =('Voyage Model'!$D$8*(365/G11*Inputs!$B$30)/Inputs!$B$32)/1000000 -> 34.360971 | D11: =CEILING(Inputs!$B$31*1000000/('Voyage Model'!$C$8*(1-H11)*(365/F11*Inputs!$B$30)),1) -> 1 | E11: =CEILING(Inputs!$B$31*1000000*Inputs!$B$32/('Voyage Model'!$D$8*(365/G11*Inputs!$B$30)/Inputs!$B$32),1) -> 17 | F11: =2*(A11/Inputs!$B$12/24)+2*Inputs!$B$13 -> 22.207207 | G11: =2*(A11/Inputs!$B$22/24)+2*Inputs!$B$23 -> 27.228831 | H11: =1-(1-Inputs!$B$14)^(A11/Inputs!$B$12/24) -> 0.019533638
A12: 8000 | B12: =('Voyage Model'!$C$8*(1-H12)*(365/F12*Inputs!$B$30))/1000000 -> 142.49263 | C12: =('Voyage Model'!$D$8*(365/G12*Inputs!$B$30)/Inputs!$B$32)/1000000 -> 30.485704 | D12: =CEILING(Inputs!$B$31*1000000/('Voyage Model'!$C$8*(1-H12)*(365/F12*Inputs!$B$30)),1) -> 1 | E12: =CEILING(Inputs!$B$31*1000000*Inputs!$B$32/('Voyage Model'!$D$8*(365/G12*Inputs!$B$30)/Inputs!$B$32),1) -> 19 | F12: =2*(A12/Inputs!$B$12/24)+2*Inputs!$B$13 -> 25.022523 | G12: =2*(A12/Inputs!$B$22/24)+2*Inputs!$B$23 -> 30.690092 | H12: =1-(1-Inputs!$B$14)^(A12/Inputs!$B$12/24) -> 0.022292834
A13: 9000 | B13: =('Voyage Model'!$C$8*(1-H13)*(365/F13*Inputs!$B$30))/1000000 -> 127.72152 | C13: =('Voyage Model'!$D$8*(365/G13*Inputs!$B$30)/Inputs!$B$32)/1000000 -> 27.395958 | D13: =CEILING(Inputs!$B$31*1000000/('Voyage Model'!$C$8*(1-H13)*(365/F13*Inputs!$B$30)),1) -> 1 | E13: =CEILING(Inputs!$B$31*1000000*Inputs!$B$32/('Voyage Model'!$D$8*(365/G13*Inputs!$B$30)/Inputs!$B$32),1) -> 21 | F13: =2*(A13/Inputs!$B$12/24)+2*Inputs!$B$13 -> 27.837838 | G13: =2*(A13/Inputs!$B$22/24)+2*Inputs!$B$23 -> 34.151354 | H13: =1-(1-Inputs!$B$14)^(A13/Inputs!$B$12/24) -> 0.025044265
A14: 10000 | B14: =('Voyage Model'!$C$8*(1-H14)*(365/F14*Inputs!$B$30))/1000000 -> 115.66462 | C14: =('Voyage Model'!$D$8*(365/G14*Inputs!$B$30)/Inputs!$B$32)/1000000 -> 24.874874 | D14: =CEILING(Inputs!$B$31*1000000/('Voyage Model'!$C$8*(1-H14)*(365/F14*Inputs!$B$30)),1) -> 1 | E14: =CEILING(Inputs!$B$31*1000000*Inputs!$B$32/('Voyage Model'!$D$8*(365/G14*Inputs!$B$30)/Inputs!$B$32),1) -> 23 | F14: =2*(A14/Inputs!$B$12/24)+2*Inputs!$B$13 -> 30.653153 | G14: =2*(A14/Inputs!$B$22/24)+2*Inputs!$B$23 -> 37.612616 | H14: =1-(1-Inputs!$B$14)^(A14/Inputs!$B$12/24) -> 0.027787954
A15: 11000 | B15: =('Voyage Model'!$C$8*(1-H15)*(365/F15*Inputs!$B$30))/1000000 -> 105.63697 | C15: =('Voyage Model'!$D$8*(365/G15*Inputs!$B$30)/Inputs!$B$32)/1000000 -> 22.778689 | D15: =CEILING(Inputs!$B$31*1000000/('Voyage Model'!$C$8*(1-H15)*(365/F15*Inputs!$B$30)),1) -> 1 | E15: =CEILING(Inputs!$B$31*1000000*Inputs!$B$32/('Voyage Model'!$D$8*(365/G15*Inputs!$B$30)/Inputs!$B$32),1) -> 25 | F15: =2*(A15/Inputs!$B$12/24)+2*Inputs!$B$13 -> 33.468468 | G15: =2*(A15/Inputs!$B$22/24)+2*Inputs!$B$23 -> 41.073877 | H15: =1-(1-Inputs!$B$14)^(A15/Inputs!$B$12/24) -> 0.030523921
A16: 12000 | B16: =('Voyage Model'!$C$8*(1-H16)*(365/F16*Inputs!$B$30))/1000000 -> 97.166222 | C16: =('Voyage Model'!$D$8*(365/G16*Inputs!$B$30)/Inputs!$B$32)/1000000 -> 21.008334 | D16: =CEILING(Inputs!$B$31*1000000/('Voyage Model'!$C$8*(1-H16)*(365/F16*Inputs!$B$30)),1) -> 2 | E16: =CEILING(Inputs!$B$31*1000000*Inputs!$B$32/('Voyage Model'!$D$8*(365/G16*Inputs!$B$30)/Inputs!$B$32),1) -> 27 | F16: =2*(A16/Inputs!$B$12/24)+2*Inputs!$B$13 -> 36.283784 | G16: =2*(A16/Inputs!$B$22/24)+2*Inputs!$B$23 -> 44.535139 | H16: =1-(1-Inputs!$B$14)^(A16/Inputs!$B$12/24) -> 0.033252189
... A44: 40000 | B44: =('Voyage Model'!$C$8*(1-H44)*(365/F44*Inputs!$B$30))/1000000 -> 28.303215 | C44: =('Voyage Model'!$D$8*(365/G44*Inputs!$B$30)/Inputs!$B$32)/1000000 -> 6.6143938 | D44: =CEILING(Inputs!$B$31*1000000/('Voyage Model'!$C$8*(1-H44)*(365/F44*Inputs!$B$30)),1) -> 4 | E44: =CEILING(Inputs!$B$31*1000000*Inputs!$B$32/('Voyage Model'!$D$8*(365/G44*Inputs!$B$30)/Inputs!$B$32),1) -> 86 | F44: =2*(A44/Inputs!$B$12/24)+2*Inputs!$B$13 -> 115.11261 | G44: =2*(A44/Inputs!$B$22/24)+2*Inputs!$B$23 -> 141.45046 | H44: =1-(1-Inputs!$B$14)^(A44/Inputs!$B$12/24) -> 0.10660403
A46: Suez reference: 10,260 km. Cape reference (primary): 21,200 km.

Sheet Sens - Boiloff
A1: Sensitivity — LH₂ Boil-off Rate
A2: At the current distance and LH2 vessel: does cargo boil-off cover the propulsion duty, and where does the boiled-off hydrogen actually go?
A4: LH₂ BOR (%/day) | B4: Covers demand (%) | C4: Useful (t, active basis) | D4: Surplus (t, active basis) | E4: VLSFO bought (t, active basis)
A5: 0 | B5: =L5 -> 0 | C5: =M5/1000/(IF(Inputs!$B$43="Per day",'Voyage Model'!$C$6,1)) -> 0 | D5: =N5/1000/(IF(Inputs!$B$43="Per day",'Voyage Model'!$C$6,1)) -> 0 | E5: =O5/(IF(Inputs!$B$43="Per day",'Voyage Model'!$C$6,1)) -> 746.05856 | G5: =1-(1-A5)^'Voyage Model'!$C$6 -> 0 | H5: ='Voyage Model'!$C$8*G5 -> 0 | I5: =H5*Inputs!$B$34*Inputs!$B$35 -> 0 | J5: =MIN(I5,'Voyage Model'!$C$19) -> 0 | K5: =MAX(0,I5-'Voyage Model'!$C$19) -> 0 | L5: =IF('Voyage Model'!$C$19=0,0,I5/'Voyage Model'!$C$19) -> 0 | M5: =J5/(Inputs!$B$34*Inputs!$B$35) -> 0 | N5: =K5/(Inputs!$B$34*Inputs!$B$35) -> 0 | O5: =MAX(0,'Voyage Model'!$C$19-I5)/Inputs!$B$33/1000 -> 746.05856
A6: 0.0005 | B6: =L6 -> 0.65801566 | C6: =M6/1000/(IF(Inputs!$B$43="Per day",'Voyage Model'!$C$6,1)) -> 164.4576 | D6: =N6/1000/(IF(Inputs!$B$43="Per day",'Voyage Model'!$C$6,1)) -> 0 | E6: =O6/(IF(Inputs!$B$43="Per day",'Voyage Model'!$C$6,1)) -> 255.14034 | G6: =1-(1-A6)^'Voyage Model'!$C$6 -> 0.014814078 | H6: ='Voyage Model'!$C$8*G6 -> 164457.6 | I6: =H6*Inputs!$B$34*Inputs!$B$35 -> 19734912 | J6: =MIN(I6,'Voyage Model'!$C$19) -> 19734912 | K6: =MAX(0,I6-'Voyage Model'!$C$19) -> 0 | L6: =IF('Voyage Model'!$C$19=0,0,I6/'Voyage Model'!$C$19) -> 0.65801566 | M6: =J6/(Inputs!$B$34*Inputs!$B$35) -> 164457.6 | N6: =K6/(Inputs!$B$34*Inputs!$B$35) -> 0 | O6: =MAX(0,'Voyage Model'!$C$19-I6)/Inputs!$B$33/1000 -> 255.14034
A7: 0.001 | B7: =L7 -> 1.3066054 | C7: =M7/1000/(IF(Inputs!$B$43="Per day",'Voyage Model'!$C$6,1)) -> 249.92962 | D7: =N7/1000/(IF(Inputs!$B$43="Per day",'Voyage Model'!$C$6,1)) -> 76.629767 | E7: =O7/(IF(Inputs!$B$43="Per day",'Voyage Model'!$C$6,1)) -> 0 | G7: =1-(1-A7)^'Voyage Model'!$C$6 -> 0.029415948 | H7: ='Voyage Model'!$C$8*G7 -> 326559.38 | I7: =H7*Inputs!$B$34*Inputs!$B$35 -> 39187126 | J7: =MIN(I7,'Voyage Model'!$C$19) -> 29991554 | K7: =MAX(0,I7-'Voyage Model'!$C$19) -> 9195572.1 | L7: =IF('Voyage Model'!$C$19=0,0,I7/'Voyage Model'!$C$19) -> 1.3066054 | M7: =J7/(Inputs!$B$34*Inputs!$B$35) -> 249929.62 | N7: =K7/(Inputs!$B$34*Inputs!$B$35) -> 76629.767 | O7: =MAX(0,'Voyage Model'!$C$19-I7)/Inputs!$B$33/1000 -> 0
A8: 0.0015 | B8: =L8 -> 1.9458996 | C8: =M8/1000/(IF(Inputs!$B$43="Per day",'Voyage Model'!$C$6,1)) -> 249.92962 | D8: =N8/1000/(IF(Inputs!$B$43="Per day",'Voyage Model'!$C$6,1)) -> 236.40832 | E8: =O8/(IF(Inputs!$B$43="Per day",'Voyage Model'!$C$6,1)) -> 0 | G8: =1-(1-A8)^'Voyage Model'!$C$6 -> 0.043808545 | H8: ='Voyage Model'!$C$8*G8 -> 486337.94 | I8: =H8*Inputs!$B$34*Inputs!$B$35 -> 58360553 | J8: =MIN(I8,'Voyage Model'!$C$19) -> 29991554 | K8: =MAX(0,I8-'Voyage Model'!$C$19) -> 28368999 | L8: =IF('Voyage Model'!$C$19=0,0,I8/'Voyage Model'!$C$19) -> 1.9458996 | M8: =J8/(Inputs!$B$34*Inputs!$B$35) -> 249929.62 | N8: =K8/(Inputs!$B$34*Inputs!$B$35) -> 236408.32 | O8: =MAX(0,'Voyage Model'!$C$19-I8)/Inputs!$B$33/1000 -> 0
A9: 0.002 | B9: =L9 -> 2.5760269 | C9: =M9/1000/(IF(Inputs!$B$43="Per day",'Voyage Model'!$C$6,1)) -> 249.92962 | D9: =N9/1000/(IF(Inputs!$B$43="Per day",'Voyage Model'!$C$6,1)) -> 393.89581 | E9: =O9/(IF(Inputs!$B$43="Per day",'Voyage Model'!$C$6,1)) -> 0 | G9: =1-(1-A9)^'Voyage Model'!$C$6 -> 0.057994767 | H9: ='Voyage Model'!$C$8*G9 -> 643825.42 | I9: =H9*Inputs!$B$34*Inputs!$B$35 -> 77259051 | J9: =MIN(I9,'Voyage Model'!$C$19) -> 29991554 | K9: =MAX(0,I9-'Voyage Model'!$C$19) -> 47267497 | L9: =IF('Voyage Model'!$C$19=0,0,I9/'Voyage Model'!$C$19) -> 2.5760269 | M9: =J9/(Inputs!$B$34*Inputs!$B$35) -> 249929.62 | N9: =K9/(Inputs!$B$34*Inputs!$B$35) -> 393895.81 | O9: =MAX(0,'Voyage Model'!$C$19-I9)/Inputs!$B$33/1000 -> 0
A10: 0.0025 | B10: =L10 -> 3.1971144 | C10: =M10/1000/(IF(Inputs!$B$43="Per day",'Voyage Model'!$C$6,1)) -> 249.92962 | D10: =N10/1000/(IF(Inputs!$B$43="Per day",'Voyage Model'!$C$6,1)) -> 549.12395 | E10: =O10/(IF(Inputs!$B$43="Per day",'Voyage Model'!$C$6,1)) -> 0 | G10: =1-(1-A10)^'Voyage Model'!$C$6 -> 0.07197747 | H10: ='Voyage Model'!$C$8*G10 -> 799053.57 | I10: =H10*Inputs!$B$34*Inputs!$B$35 -> 95886428 | J10: =MIN(I10,'Voyage Model'!$C$19) -> 29991554 | K10: =MAX(0,I10-'Voyage Model'!$C$19) -> 65894874 | L10: =IF('Voyage Model'!$C$19=0,0,I10/'Voyage Model'!$C$19) -> 3.1971144 | M10: =J10/(Inputs!$B$34*Inputs!$B$35) -> 249929.62 | N10: =K10/(Inputs!$B$34*Inputs!$B$35) -> 549123.95 | O10: =MAX(0,'Voyage Model'!$C$19-I10)/Inputs!$B$33/1000 -> 0
A11: 0.003 | B11: =L11 -> 3.8092871 | C11: =M11/1000/(IF(Inputs!$B$43="Per day",'Voyage Model'!$C$6,1)) -> 249.92962 | D11: =N11/1000/(IF(Inputs!$B$43="Per day",'Voyage Model'!$C$6,1)) -> 702.12406 | E11: =O11/(IF(Inputs!$B$43="Per day",'Voyage Model'!$C$6,1)) -> 0 | G11: =1-(1-A11)^'Voyage Model'!$C$6 -> 0.085759476 | H11: ='Voyage Model'!$C$8*G11 -> 952053.68 | I11: =H11*Inputs!$B$34*Inputs!$B$35 -> 1.1424644e+08 | J11: =MIN(I11,'Voyage Model'!$C$19) -> 29991554 | K11: =MAX(0,I11-'Voyage Model'!$C$19) -> 84254887 | L11: =IF('Voyage Model'!$C$19=0,0,I11/'Voyage Model'!$C$19) -> 3.8092871 | M11: =J11/(Inputs!$B$34*Inputs!$B$35) -> 249929.62 | N11: =K11/(Inputs!$B$34*Inputs!$B$35) -> 702124.06 | O11: =MAX(0,'Voyage Model'!$C$19-I11)/Inputs!$B$33/1000 -> 0
A12: 0.0035 | B12: =L12 -> 4.4126688 | C12: =M12/1000/(IF(Inputs!$B$43="Per day",'Voyage Model'!$C$6,1)) -> 249.92962 | D12: =N12/1000/(IF(Inputs!$B$43="Per day",'Voyage Model'!$C$6,1)) -> 852.92702 | E12: =O12/(IF(Inputs!$B$43="Per day",'Voyage Model'!$C$6,1)) -> 0 | G12: =1-(1-A12)^'Voyage Model'!$C$6 -> 0.099343566 | H12: ='Voyage Model'!$C$8*G12 -> 1102856.6 | I12: =H12*Inputs!$B$34*Inputs!$B$35 -> 1.323428e+08 | J12: =MIN(I12,'Voyage Model'!$C$19) -> 29991554 | K12: =MAX(0,I12-'Voyage Model'!$C$19) -> 1.0235124e+08 | L12: =IF('Voyage Model'!$C$19=0,0,I12/'Voyage Model'!$C$19) -> 4.4126688 | M12: =J12/(Inputs!$B$34*Inputs!$B$35) -> 249929.62 | N12: =K12/(Inputs!$B$34*Inputs!$B$35) -> 852927.02 | O12: =MAX(0,'Voyage Model'!$C$19-I12)/Inputs!$B$33/1000 -> 0
A13: 0.004 | B13: =L13 -> 5.0073814 | C13: =M13/1000/(IF(Inputs!$B$43="Per day",'Voyage Model'!$C$6,1)) -> 249.92962 | D13: =N13/1000/(IF(Inputs!$B$43="Per day",'Voyage Model'!$C$6,1)) -> 1001.5633 | E13: =O13/(IF(Inputs!$B$43="Per day",'Voyage Model'!$C$6,1)) -> 0 | G13: =1-(1-A13)^'Voyage Model'!$C$6 -> 0.11273248 | H13: ='Voyage Model'!$C$8*G13 -> 1251492.9 | I13: =H13*Inputs!$B$34*Inputs!$B$35 -> 1.5017915e+08 | J13: =MIN(I13,'Voyage Model'!$C$19) -> 29991554 | K13: =MAX(0,I13-'Voyage Model'!$C$19) -> 1.201876e+08 | L13: =IF('Voyage Model'!$C$19=0,0,I13/'Voyage Model'!$C$19) -> 5.0073814 | M13: =J13/(Inputs!$B$34*Inputs!$B$35) -> 249929.62 | N13: =K13/(Inputs!$B$34*Inputs!$B$35) -> 1001563.3 | O13: =MAX(0,'Voyage Model'!$C$19-I13)/Inputs!$B$33/1000 -> 0
A14: 0.0045 | B14: =L14 -> 5.5935451 | C14: =M14/1000/(IF(Inputs!$B$43="Per day",'Voyage Model'!$C$6,1)) -> 249.92962 | D14: =N14/1000/(IF(Inputs!$B$43="Per day",'Voyage Model'!$C$6,1)) -> 1148.063 | E14: =O14/(IF(Inputs!$B$43="Per day",'Voyage Model'!$C$6,1)) -> 0 | G14: =1-(1-A14)^'Voyage Model'!$C$6 -> 0.12592894 | H14: ='Voyage Model'!$C$8*G14 -> 1397992.6 | I14: =H14*Inputs!$B$34*Inputs!$B$35 -> 1.6775911e+08 | J14: =MIN(I14,'Voyage Model'!$C$19) -> 29991554 | K14: =MAX(0,I14-'Voyage Model'!$C$19) -> 1.3776756e+08 | L14: =IF('Voyage Model'!$C$19=0,0,I14/'Voyage Model'!$C$19) -> 5.5935451 | M14: =J14/(Inputs!$B$34*Inputs!$B$35) -> 249929.62 | N14: =K14/(Inputs!$B$34*Inputs!$B$35) -> 1148063 | O14: =MAX(0,'Voyage Model'!$C$19-I14)/Inputs!$B$33/1000 -> 0
A15: 0.005 | B15: =L15 -> 6.1712786 | C15: =M15/1000/(IF(Inputs!$B$43="Per day",'Voyage Model'!$C$6,1)) -> 249.92962 | D15: =N15/1000/(IF(Inputs!$B$43="Per day",'Voyage Model'!$C$6,1)) -> 1292.4557 | E15: =O15/(IF(Inputs!$B$43="Per day",'Voyage Model'!$C$6,1)) -> 0 | G15: =1-(1-A15)^'Voyage Model'!$C$6 -> 0.13893561 | H15: ='Voyage Model'!$C$8*G15 -> 1542385.3 | I15: =H15*Inputs!$B$34*Inputs!$B$35 -> 1.8508624e+08 | J15: =MIN(I15,'Voyage Model'!$C$19) -> 29991554 | K15: =MAX(0,I15-'Voyage Model'!$C$19) -> 1.5509468e+08 | L15: =IF('Voyage Model'!$C$19=0,0,I15/'Voyage Model'!$C$19) -> 6.1712786 | M15: =J15/(Inputs!$B$34*Inputs!$B$35) -> 249929.62 | N15: =K15/(Inputs!$B$34*Inputs!$B$35) -> 1292455.7 | O15: =MAX(0,'Voyage Model'!$C$19-I15)/Inputs!$B$33/1000 -> 0
A16: 0.0055 | B16: =L16 -> 6.7406991 | C16: =M16/1000/(IF(Inputs!$B$43="Per day",'Voyage Model'!$C$6,1)) -> 249.92962 | D16: =N16/1000/(IF(Inputs!$B$43="Per day",'Voyage Model'!$C$6,1)) -> 1434.7707 | E16: =O16/(IF(Inputs!$B$43="Per day",'Voyage Model'!$C$6,1)) -> 0 | G16: =1-(1-A16)^'Voyage Model'!$C$6 -> 0.15175512 | H16: ='Voyage Model'!$C$8*G16 -> 1684700.3 | I16: =H16*Inputs!$B$34*Inputs!$B$35 -> 2.0216404e+08 | J16: =MIN(I16,'Voyage Model'!$C$19) -> 29991554 | K16: =MAX(0,I16-'Voyage Model'!$C$19) -> 1.7217249e+08 | L16: =IF('Voyage Model'!$C$19=0,0,I16/'Voyage Model'!$C$19) -> 6.7406991 | M16: =J16/(Inputs!$B$34*Inputs!$B$35) -> 249929.62 | N16: =K16/(Inputs!$B$34*Inputs!$B$35) -> 1434770.7 | O16: =MAX(0,'Voyage Model'!$C$19-I16)/Inputs!$B$33/1000 -> 0
... A85: 0.04 | B85: =L85 -> 31.281342 | C85: =M85/1000/(IF(Inputs!$B$43="Per day",'Voyage Model'!$C$6,1)) -> 249.92962 | D85: =N85/1000/(IF(Inputs!$B$43="Per day",'Voyage Model'!$C$6,1)) -> 7568.2042 | E85: =O85/(IF(Inputs!$B$43="Per day",'Voyage Model'!$C$6,1)) -> 0 | G85: =1-(1-A85)^'Voyage Model'!$C$6 -> 0.70424502 | H85: ='Voyage Model'!$C$8*G85 -> 7818133.8 | I85: =H85*Inputs!$B$34*Inputs!$B$35 -> 9.3817606e+08 | J85: =MIN(I85,'Voyage Model'!$C$19) -> 29991554 | K85: =MAX(0,I85-'Voyage Model'!$C$19) -> 9.0818451e+08 | L85: =IF('Voyage Model'!$C$19=0,0,I85/'Voyage Model'!$C$19) -> 31.281342 | M85: =J85/(Inputs!$B$34*Inputs!$B$35) -> 249929.62 | N85: =K85/(Inputs!$B$34*Inputs!$B$35) -> 7568204.2 | O85: =MAX(0,'Voyage Model'!$C$19-I85)/Inputs!$B$33/1000 -> 0
A87: Column B: 100% = boil-off exactly meets propulsion demand.
A88: RSER-2026 literature reference (unpromoted): ~3.44%/day for a comparable vessel class.

Sheet Sens - H2Price
A1: Sensitivity — Hydrogen Value
A2: Cost of managing boil-off (active mode) per kg H₂ delivered, against the value placed on delivered hydrogen. At the current distance, LH2 vessel and NH3 vessel.
A4: H₂ value (USD/kg) | B4: LH₂ cost (USD/kg) | C4: NH₃ cost (USD/kg)
A5: 0 | B5: =('Voyage Model'!$C$32*A5+'Voyage Model'!$C$40)/'Voyage Model'!$C$33 -> -0.042804708 | C5: ='Voyage Model'!$D$42 -> 0.0090088785
A6: 0.25 | B6: =('Voyage Model'!$C$32*A6+'Voyage Model'!$C$40)/'Voyage Model'!$C$33 -> -0.027413401 | C6: ='Voyage Model'!$D$42 -> 0.0090088785
A7: 0.5 | B7: =('Voyage Model'!$C$32*A7+'Voyage Model'!$C$40)/'Voyage Model'!$C$33 -> -0.012022094 | C7: ='Voyage Model'!$D$42 -> 0.0090088785
A8: 0.75 | B8: =('Voyage Model'!$C$32*A8+'Voyage Model'!$C$40)/'Voyage Model'!$C$33 -> 0.0033692132 | C8: ='Voyage Model'!$D$42 -> 0.0090088785
A9: 1 | B9: =('Voyage Model'!$C$32*A9+'Voyage Model'!$C$40)/'Voyage Model'!$C$33 -> 0.01876052 | C9: ='Voyage Model'!$D$42 -> 0.0090088785
A10: 1.25 | B10: =('Voyage Model'!$C$32*A10+'Voyage Model'!$C$40)/'Voyage Model'!$C$33 -> 0.034151827 | C10: ='Voyage Model'!$D$42 -> 0.0090088785
A11: 1.5 | B11: =('Voyage Model'!$C$32*A11+'Voyage Model'!$C$40)/'Voyage Model'!$C$33 -> 0.049543134 | C11: ='Voyage Model'!$D$42 -> 0.0090088785
A12: 1.75 | B12: =('Voyage Model'!$C$32*A12+'Voyage Model'!$C$40)/'Voyage Model'!$C$33 -> 0.064934441 | C12: ='Voyage Model'!$D$42 -> 0.0090088785
A13: 2 | B13: =('Voyage Model'!$C$32*A13+'Voyage Model'!$C$40)/'Voyage Model'!$C$33 -> 0.080325748 | C13: ='Voyage Model'!$D$42 -> 0.0090088785
A14: 2.25 | B14: =('Voyage Model'!$C$32*A14+'Voyage Model'!$C$40)/'Voyage Model'!$C$33 -> 0.095717055 | C14: ='Voyage Model'!$D$42 -> 0.0090088785
A15: 2.5 | B15: =('Voyage Model'!$C$32*A15+'Voyage Model'!$C$40)/'Voyage Model'!$C$33 -> 0.11110836 | C15: ='Voyage Model'!$D$42 -> 0.0090088785
A16: 2.75 | B16: =('Voyage Model'!$C$32*A16+'Voyage Model'!$C$40)/'Voyage Model'!$C$33 -> 0.12649967 | C16: ='Voyage Model'!$D$42 -> 0.0090088785
... A53: 12 | B53: =('Voyage Model'!$C$32*A53+'Voyage Model'!$C$40)/'Voyage Model'!$C$33 -> 0.69597803 | C53: ='Voyage Model'!$D$42 -> 0.0090088785
A55: Breakeven H₂ value (active mode): see Voyage Model!$B$51

Sheet Decision Map
A1: Decision Map — Hydrogen Value × LH₂ Vessel Size
A2: At what hydrogen price and LH2 hull size does LH2 beat ammonia on boil-off cost? Grid = LH2 cost minus NH3 cost, USD/kg (negative/green = LH2 cheaper). Duty scales with hull size per the Inputs exponent, anchored on the LH2 vessel's own selected capacity/duty pair (Inputs).
A4: LH₂ capacity (m³) | B4: Duty at this size (t/day) | C4: Parity H₂ price (USD/kg) | E4: 0 | F4: 0.25 | G4: 0.5 | H4: 0.75 | I4: 1 | J4: 1.25 | K4: 1.5 | L4: 1.75 | M4: 2 | N4: 2.25 | O4: 2.5 | P4: 2.75 | Q4: 3 | R4: 3.25 | S4: 3.5 | T4: 3.75 | U4: 4
A5: 20000 | B5: =Inputs!$B$15*(A5/Inputs!$B$9)^Inputs!$B$44 -> 6.2456693 | C5: =IF(Y5=0,"n/a",('Voyage Model'!$D$42*AC5+AB5*Inputs!$B$40)/Y5) -> 1.5359153 | E5: =(Y5*E$4-AB5*Inputs!$B$40)/AC5-('Voyage Model'!$D$42) -> -0.094558975 | F5: =(Y5*F$4-AB5*Inputs!$B$40)/AC5-('Voyage Model'!$D$42) -> -0.079167668 | G5: =(Y5*G$4-AB5*Inputs!$B$40)/AC5-('Voyage Model'!$D$42) -> -0.063776361 | H5: =(Y5*H$4-AB5*Inputs!$B$40)/AC5-('Voyage Model'!$D$42) -> -0.048385054 | I5: =(Y5*I$4-AB5*Inputs!$B$40)/AC5-('Voyage Model'!$D$42) -> -0.032993747 | J5: =(Y5*J$4-AB5*Inputs!$B$40)/AC5-('Voyage Model'!$D$42) -> -0.01760244 | K5: =(Y5*K$4-AB5*Inputs!$B$40)/AC5-('Voyage Model'!$D$42) -> -0.0022111327 | L5: =(Y5*L$4-AB5*Inputs!$B$40)/AC5-('Voyage Model'!$D$42) -> 0.013180174 | M5: =(Y5*M$4-AB5*Inputs!$B$40)/AC5-('Voyage Model'!$D$42) -> 0.028571481 | N5: =(Y5*N$4-AB5*Inputs!$B$40)/AC5-('Voyage Model'!$D$42) -> 0.043962788 | O5: =(Y5*O$4-AB5*Inputs!$B$40)/AC5-('Voyage Model'!$D$42) -> 0.059354095 | P5: =(Y5*P$4-AB5*Inputs!$B$40)/AC5-('Voyage Model'!$D$42) -> 0.074745402 | Q5: =(Y5*Q$4-AB5*Inputs!$B$40)/AC5-('Voyage Model'!$D$42) -> 0.090136709 | R5: =(Y5*R$4-AB5*Inputs!$B$40)/AC5-('Voyage Model'!$D$42) -> 0.10552802 | S5: =(Y5*S$4-AB5*Inputs!$B$40)/AC5-('Voyage Model'!$D$42) -> 0.12091932 | T5: =(Y5*T$4-AB5*Inputs!$B$40)/AC5-('Voyage Model'!$D$42) -> 0.13631063 | U5: =(Y5*U$4-AB5*Inputs!$B$40)/AC5-('Voyage Model'!$D$42) -> 0.15170194 | X5: =A5*Inputs!$B$10*Inputs!$B$11 -> 1387680 | Y5: =X5*'Voyage Model'!$C$9 -> 80478.178 | Z5: =B5*1000*'Voyage Model'!$C$6*Inputs!$B$33 -> 7492693.2 | AA5: =Y5*Inputs!$B$34*Inputs!$B$35 -> 9657381.4 | AB5: =MIN(AA5,Z5)/Inputs!$B$33/1000 -> 186.3854 | AC5: =X5*(1-'Voyage Model'!$C$9) -> 1307201.8
A6: 30000 | B6: =Inputs!$B$15*(A6/Inputs!$B$9)^Inputs!$B$44 -> 8.1852483 | C6: =IF(Y6=0,"n/a",('Voyage Model'!$D$42*AC6+AB6*Inputs!$B$40)/Y6) -> 1.3604087 | E6: =(Y6*E$4-AB6*Inputs!$B$40)/AC6-('Voyage Model'!$D$42) -> -0.083753873 | F6: =(Y6*F$4-AB6*Inputs!$B$40)/AC6-('Voyage Model'!$D$42) -> -0.068362566 | G6: =(Y6*G$4-AB6*Inputs!$B$40)/AC6-('Voyage Model'!$D$42) -> -0.052971259 | H6: =(Y6*H$4-AB6*Inputs!$B$40)/AC6-('Voyage Model'!$D$42) -> -0.037579952 | I6: =(Y6*I$4-AB6*Inputs!$B$40)/AC6-('Voyage Model'!$D$42) -> -0.022188645 | J6: =(Y6*J$4-AB6*Inputs!$B$40)/AC6-('Voyage Model'!$D$42) -> -0.0067973378 | K6: =(Y6*K$4-AB6*Inputs!$B$40)/AC6-('Voyage Model'!$D$42) -> 0.0085939692 | L6: =(Y6*L$4-AB6*Inputs!$B$40)/AC6-('Voyage Model'!$D$42) -> 0.023985276 | M6: =(Y6*M$4-AB6*Inputs!$B$40)/AC6-('Voyage Model'!$D$42) -> 0.039376583 | N6: =(Y6*N$4-AB6*Inputs!$B$40)/AC6-('Voyage Model'!$D$42) -> 0.05476789 | O6: =(Y6*O$4-AB6*Inputs!$B$40)/AC6-('Voyage Model'!$D$42) -> 0.070159197 | P6: =(Y6*P$4-AB6*Inputs!$B$40)/AC6-('Voyage Model'!$D$42) -> 0.085550504 | Q6: =(Y6*Q$4-AB6*Inputs!$B$40)/AC6-('Voyage Model'!$D$42) -> 0.10094181 | R6: =(Y6*R$4-AB6*Inputs!$B$40)/AC6-('Voyage Model'!$D$42) -> 0.11633312 | S6: =(Y6*S$4-AB6*Inputs!$B$40)/AC6-('Voyage Model'!$D$42) -> 0.13172443 | T6: =(Y6*T$4-AB6*Inputs!$B$40)/AC6-('Voyage Model'!$D$42) -> 0.14711573 | U6: =(Y6*U$4-AB6*Inputs!$B$40)/AC6-('Voyage Model'!$D$42) -> 0.16250704 | X6: =A6*Inputs!$B$10*Inputs!$B$11 -> 2081520 | Y6: =X6*'Voyage Model'!$C$9 -> 120717.27 | Z6: =B6*1000*'Voyage Model'!$C$6*Inputs!$B$33 -> 9819532.6 | AA6: =Y6*Inputs!$B$34*Inputs!$B$35 -> 14486072 | AB6: =MIN(AA6,Z6)/Inputs!$B$33/1000 -> 244.26698 | AC6: =X6*(1-'Voyage Model'!$C$9) -> 1960802.7
A7: 40000 | B7: =Inputs!$B$15*(A7/Inputs!$B$9)^Inputs!$B$44 -> 9.916673 | C7: =IF(Y7=0,"n/a",('Voyage Model'!$D$42*AC7+AB7*Inputs!$B$40)/Y7) -> 1.2494996 | E7: =(Y7*E$4-AB7*Inputs!$B$40)/AC7-('Voyage Model'!$D$42) -> -0.076925725 | F7: =(Y7*F$4-AB7*Inputs!$B$40)/AC7-('Voyage Model'!$D$42) -> -0.061534418 | G7: =(Y7*G$4-AB7*Inputs!$B$40)/AC7-('Voyage Model'!$D$42) -> -0.046143111 | H7: =(Y7*H$4-AB7*Inputs!$B$40)/AC7-('Voyage Model'!$D$42) -> -0.030751804 | I7: =(Y7*I$4-AB7*Inputs!$B$40)/AC7-('Voyage Model'!$D$42) -> -0.015360497 | J7: =(Y7*J$4-AB7*Inputs!$B$40)/AC7-('Voyage Model'!$D$42) -> 3.0809845e-05 | K7: =(Y7*K$4-AB7*Inputs!$B$40)/AC7-('Voyage Model'!$D$42) -> 0.015422117 | L7: =(Y7*L$4-AB7*Inputs!$B$40)/AC7-('Voyage Model'!$D$42) -> 0.030813424 | M7: =(Y7*M$4-AB7*Inputs!$B$40)/AC7-('Voyage Model'!$D$42) -> 0.046204731 | N7: =(Y7*N$4-AB7*Inputs!$B$40)/AC7-('Voyage Model'!$D$42) -> 0.061596038 | O7: =(Y7*O$4-AB7*Inputs!$B$40)/AC7-('Voyage Model'!$D$42) -> 0.076987345 | P7: =(Y7*P$4-AB7*Inputs!$B$40)/AC7-('Voyage Model'!$D$42) -> 0.092378652 | Q7: =(Y7*Q$4-AB7*Inputs!$B$40)/AC7-('Voyage Model'!$D$42) -> 0.10776996 | R7: =(Y7*R$4-AB7*Inputs!$B$40)/AC7-('Voyage Model'!$D$42) -> 0.12316127 | S7: =(Y7*S$4-AB7*Inputs!$B$40)/AC7-('Voyage Model'!$D$42) -> 0.13855257 | T7: =(Y7*T$4-AB7*Inputs!$B$40)/AC7-('Voyage Model'!$D$42) -> 0.15394388 | U7: =(Y7*U$4-AB7*Inputs!$B$40)/AC7-('Voyage Model'!$D$42) -> 0.16933519 | X7: =A7*Inputs!$B$10*Inputs!$B$11 -> 2775360 | Y7: =X7*'Voyage Model'!$C$9 -> 160956.36 | Z7: =B7*1000*'Voyage Model'!$C$6*Inputs!$B$33 -> 11896657 | AA7: =Y7*Inputs!$B$34*Inputs!$B$35 -> 19314763 | AB7: =MIN(AA7,Z7)/Inputs!$B$33/1000 -> 295.93675 | AC7: =X7*(1-'Voyage Model'!$C$9) -> 2614403.6
A8: 50000 | B8: =Inputs!$B$15*(A8/Inputs!$B$9)^Inputs!$B$44 -> 11.508136 | C8: =IF(Y8=0,"n/a",('Voyage Model'!$D$42*AC8+AB8*Inputs!$B$40)/Y8) -> 1.1704981 | E8: =(Y8*E$4-AB8*Inputs!$B$40)/AC8-('Voyage Model'!$D$42) -> -0.072061984 | F8: =(Y8*F$4-AB8*Inputs!$B$40)/AC8-('Voyage Model'!$D$42) -> -0.056670677 | G8: =(Y8*G$4-AB8*Inputs!$B$40)/AC8-('Voyage Model'!$D$42) -> -0.04127937 | H8: =(Y8*H$4-AB8*Inputs!$B$40)/AC8-('Voyage Model'!$D$42) -> -0.025888063 | I8: =(Y8*I$4-AB8*Inputs!$B$40)/AC8-('Voyage Model'!$D$42) -> -0.010496756 | J8: =(Y8*J$4-AB8*Inputs!$B$40)/AC8-('Voyage Model'!$D$42) -> 0.0048945513 | K8: =(Y8*K$4-AB8*Inputs!$B$40)/AC8-('Voyage Model'!$D$42) -> 0.020285858 | L8: =(Y8*L$4-AB8*Inputs!$B$40)/AC8-('Voyage Model'!$D$42) -> 0.035677165 | M8: =(Y8*M$4-AB8*Inputs!$B$40)/AC8-('Voyage Model'!$D$42) -> 0.051068472 | N8: =(Y8*N$4-AB8*Inputs!$B$40)/AC8-('Voyage Model'!$D$42) -> 0.066459779 | O8: =(Y8*O$4-AB8*Inputs!$B$40)/AC8-('Voyage Model'!$D$42) -> 0.081851086 | P8: =(Y8*P$4-AB8*Inputs!$B$40)/AC8-('Voyage Model'!$D$42) -> 0.097242393 | Q8: =(Y8*Q$4-AB8*Inputs!$B$40)/AC8-('Voyage Model'!$D$42) -> 0.1126337 | R8: =(Y8*R$4-AB8*Inputs!$B$40)/AC8-('Voyage Model'!$D$42) -> 0.12802501 | S8: =(Y8*S$4-AB8*Inputs!$B$40)/AC8-('Voyage Model'!$D$42) -> 0.14341631 | T8: =(Y8*T$4-AB8*Inputs!$B$40)/AC8-('Voyage Model'!$D$42) -> 0.15880762 | U8: =(Y8*U$4-AB8*Inputs!$B$40)/AC8-('Voyage Model'!$D$42) -> 0.17419893 | X8: =A8*Inputs!$B$10*Inputs!$B$11 -> 3469200 | Y8: =X8*'Voyage Model'!$C$9 -> 201195.45 | Z8: =B8*1000*'Voyage Model'!$C$6*Inputs!$B$33 -> 13805875 | AA8: =Y8*Inputs!$B$34*Inputs!$B$35 -> 24143453 | AB8: =MIN(AA8,Z8)/Inputs!$B$33/1000 -> 343.42972 | AC8: =X8*(1-'Voyage Model'!$C$9) -> 3268004.6
A9: 60000 | B9: =Inputs!$B$15*(A9/Inputs!$B$9)^Inputs!$B$44 -> 12.996274 | C9: =IF(Y9=0,"n/a",('Voyage Model'!$D$42*AC9+AB9*Inputs!$B$40)/Y9) -> 1.1101677 | E9: =(Y9*E$4-AB9*Inputs!$B$40)/AC9-('Voyage Model'!$D$42) -> -0.068347728 | F9: =(Y9*F$4-AB9*Inputs!$B$40)/AC9-('Voyage Model'!$D$42) -> -0.052956421 | G9: =(Y9*G$4-AB9*Inputs!$B$40)/AC9-('Voyage Model'!$D$42) -> -0.037565114 | H9: =(Y9*H$4-AB9*Inputs!$B$40)/AC9-('Voyage Model'!$D$42) -> -0.022173807 | I9: =(Y9*I$4-AB9*Inputs!$B$40)/AC9-('Voyage Model'!$D$42) -> -0.0067825004 | J9: =(Y9*J$4-AB9*Inputs!$B$40)/AC9-('Voyage Model'!$D$42) -> 0.0086088066 | K9: =(Y9*K$4-AB9*Inputs!$B$40)/AC9-('Voyage Model'!$D$42) -> 0.024000114 | L9: =(Y9*L$4-AB9*Inputs!$B$40)/AC9-('Voyage Model'!$D$42) -> 0.039391421 | M9: =(Y9*M$4-AB9*Inputs!$B$40)/AC9-('Voyage Model'!$D$42) -> 0.054782728 | N9: =(Y9*N$4-AB9*Inputs!$B$40)/AC9-('Voyage Model'!$D$42) -> 0.070174035 | O9: =(Y9*O$4-AB9*Inputs!$B$40)/AC9-('Voyage Model'!$D$42) -> 0.085565341 | P9: =(Y9*P$4-AB9*Inputs!$B$40)/AC9-('Voyage Model'!$D$42) -> 0.10095665 | Q9: =(Y9*Q$4-AB9*Inputs!$B$40)/AC9-('Voyage Model'!$D$42) -> 0.11634796 | R9: =(Y9*R$4-AB9*Inputs!$B$40)/AC9-('Voyage Model'!$D$42) -> 0.13173926 | S9: =(Y9*S$4-AB9*Inputs!$B$40)/AC9-('Voyage Model'!$D$42) -> 0.14713057 | T9: =(Y9*T$4-AB9*Inputs!$B$40)/AC9-('Voyage Model'!$D$42) -> 0.16252188 | U9: =(Y9*U$4-AB9*Inputs!$B$40)/AC9-('Voyage Model'!$D$42) -> 0.17791318 | X9: =A9*Inputs!$B$10*Inputs!$B$11 -> 4163040 | Y9: =X9*'Voyage Model'!$C$9 -> 241434.53 | Z9: =B9*1000*'Voyage Model'!$C$6*Inputs!$B$33 -> 15591138 | AA9: =Y9*Inputs!$B$34*Inputs!$B$35 -> 28972144 | AB9: =MIN(AA9,Z9)/Inputs!$B$33/1000 -> 387.83926 | AC9: =X9*(1-'Voyage Model'!$C$9) -> 3921605.5
A10: 70000 | B10: =Inputs!$B$15*(A10/Inputs!$B$9)^Inputs!$B$44 -> 14.403644 | C10: =IF(Y10=0,"n/a",('Voyage Model'!$D$42*AC10+AB10*Inputs!$B$40)/Y10) -> 1.0619403 | E10: =(Y10*E$4-AB10*Inputs!$B$40)/AC10-('Voyage Model'!$D$42) -> -0.065378594 | F10: =(Y10*F$4-AB10*Inputs!$B$40)/AC10-('Voyage Model'!$D$42) -> -0.049987287 | G10: =(Y10*G$4-AB10*Inputs!$B$40)/AC10-('Voyage Model'!$D$42) -> -0.03459598 | H10: =(Y10*H$4-AB10*Inputs!$B$40)/AC10-('Voyage Model'!$D$42) -> -0.019204673 | I10: =(Y10*I$4-AB10*Inputs!$B$40)/AC10-('Voyage Model'!$D$42) -> -0.0038133661 | J10: =(Y10*J$4-AB10*Inputs!$B$40)/AC10-('Voyage Model'!$D$42) -> 0.011577941 | K10: =(Y10*K$4-AB10*Inputs!$B$40)/AC10-('Voyage Model'!$D$42) -> 0.026969248 | L10: =(Y10*L$4-AB10*Inputs!$B$40)/AC10-('Voyage Model'!$D$42) -> 0.042360555 | M10: =(Y10*M$4-AB10*Inputs!$B$40)/AC10-('Voyage Model'!$D$42) -> 0.057751862 | N10: =(Y10*N$4-AB10*Inputs!$B$40)/AC10-('Voyage Model'!$D$42) -> 0.073143169 | O10: =(Y10*O$4-AB10*Inputs!$B$40)/AC10-('Voyage Model'!$D$42) -> 0.088534476 | P10: =(Y10*P$4-AB10*Inputs!$B$40)/AC10-('Voyage Model'!$D$42) -> 0.10392578 | Q10: =(Y10*Q$4-AB10*Inputs!$B$40)/AC10-('Voyage Model'!$D$42) -> 0.11931709 | R10: =(Y10*R$4-AB10*Inputs!$B$40)/AC10-('Voyage Model'!$D$42) -> 0.1347084 | S10: =(Y10*S$4-AB10*Inputs!$B$40)/AC10-('Voyage Model'!$D$42) -> 0.1500997 | T10: =(Y10*T$4-AB10*Inputs!$B$40)/AC10-('Voyage Model'!$D$42) -> 0.16549101 | U10: =(Y10*U$4-AB10*Inputs!$B$40)/AC10-('Voyage Model'!$D$42) -> 0.18088232 | X10: =A10*Inputs!$B$10*Inputs!$B$11 -> 4856880 | Y10: =X10*'Voyage Model'!$C$9 -> 281673.62 | Z10: =B10*1000*'Voyage Model'!$C$6*Inputs!$B$33 -> 17279506 | AA10: =Y10*Inputs!$B$34*Inputs!$B$35 -> 33800835 | AB10: =MIN(AA10,Z10)/Inputs!$B$33/1000 -> 429.83847 | AC10: =X10*(1-'Voyage Model'!$C$9) -> 4575206.4
A11: 80000 | B11: =Inputs!$B$15*(A11/Inputs!$B$9)^Inputs!$B$44 -> 15.745375 | C11: =IF(Y11=0,"n/a",('Voyage Model'!$D$42*AC11+AB11*Inputs!$B$40)/Y11) -> 1.0221187 | E11: =(Y11*E$4-AB11*Inputs!$B$40)/AC11-('Voyage Model'!$D$42) -> -0.062926972 | F11: =(Y11*F$4-AB11*Inputs!$B$40)/AC11-('Voyage Model'!$D$42) -> -0.047535665 | G11: =(Y11*G$4-AB11*Inputs!$B$40)/AC11-('Voyage Model'!$D$42) -> -0.032144358 | H11: =(Y11*H$4-AB11*Inputs!$B$40)/AC11-('Voyage Model'!$D$42) -> -0.016753051 | I11: =(Y11*I$4-AB11*Inputs!$B$40)/AC11-('Voyage Model'!$D$42) -> -0.0013617437 | J11: =(Y11*J$4-AB11*Inputs!$B$40)/AC11-('Voyage Model'!$D$42) -> 0.014029563 | K11: =(Y11*K$4-AB11*Inputs!$B$40)/AC11-('Voyage Model'!$D$42) -> 0.02942087 | L11: =(Y11*L$4-AB11*Inputs!$B$40)/AC11-('Voyage Model'!$D$42) -> 0.044812177 | M11: =(Y11*M$4-AB11*Inputs!$B$40)/AC11-('Voyage Model'!$D$42) -> 0.060203484 | N11: =(Y11*N$4-AB11*Inputs!$B$40)/AC11-('Voyage Model'!$D$42) -> 0.075594791 | O11: =(Y11*O$4-AB11*Inputs!$B$40)/AC11-('Voyage Model'!$D$42) -> 0.090986098 | P11: =(Y11*P$4-AB11*Inputs!$B$40)/AC11-('Voyage Model'!$D$42) -> 0.10637741 | Q11: =(Y11*Q$4-AB11*Inputs!$B$40)/AC11-('Voyage Model'!$D$42) -> 0.12176871 | R11: =(Y11*R$4-AB11*Inputs!$B$40)/AC11-('Voyage Model'!$D$42) -> 0.13716002 | S11: =(Y11*S$4-AB11*Inputs!$B$40)/AC11-('Voyage Model'!$D$42) -> 0.15255133 | T11: =(Y11*T$4-AB11*Inputs!$B$40)/AC11-('Voyage Model'!$D$42) -> 0.16794263 | U11: =(Y11*U$4-AB11*Inputs!$B$40)/AC11-('Voyage Model'!$D$42) -> 0.18333394 | X11: =A11*Inputs!$B$10*Inputs!$B$11 -> 5550720 | Y11: =X11*'Voyage Model'!$C$9 -> 321912.71 | Z11: =B11*1000*'Voyage Model'!$C$6*Inputs!$B$33 -> 18889130 | AA11: =Y11*Inputs!$B$34*Inputs!$B$35 -> 38629525 | AB11: =MIN(AA11,Z11)/Inputs!$B$33/1000 -> 469.87886 | AC11: =X11*(1-'Voyage Model'!$C$9) -> 5228807.3
A12: 90000 | B12: =Inputs!$B$15*(A12/Inputs!$B$9)^Inputs!$B$44 -> 17.032239 | C12: =IF(Y12=0,"n/a",('Voyage Model'!$D$42*AC12+AB12*Inputs!$B$40)/Y12) -> 0.98843368 | E12: =(Y12*E$4-AB12*Inputs!$B$40)/AC12-('Voyage Model'!$D$42) -> -0.060853145 | F12: =(Y12*F$4-AB12*Inputs!$B$40)/AC12-('Voyage Model'!$D$42) -> -0.045461838 | G12: =(Y12*G$4-AB12*Inputs!$B$40)/AC12-('Voyage Model'!$D$42) -> -0.030070531 | H12: =(Y12*H$4-AB12*Inputs!$B$40)/AC12-('Voyage Model'!$D$42) -> -0.014679224 | I12: =(Y12*I$4-AB12*Inputs!$B$40)/AC12-('Voyage Model'!$D$42) -> 0.00071208291 | J12: =(Y12*J$4-AB12*Inputs!$B$40)/AC12-('Voyage Model'!$D$42) -> 0.01610339 | K12: =(Y12*K$4-AB12*Inputs!$B$40)/AC12-('Voyage Model'!$D$42) -> 0.031494697 | L12: =(Y12*L$4-AB12*Inputs!$B$40)/AC12-('Voyage Model'!$D$42) -> 0.046886004 | M12: =(Y12*M$4-AB12*Inputs!$B$40)/AC12-('Voyage Model'!$D$42) -> 0.062277311 | N12: =(Y12*N$4-AB12*Inputs!$B$40)/AC12-('Voyage Model'!$D$42) -> 0.077668618 | O12: =(Y12*O$4-AB12*Inputs!$B$40)/AC12-('Voyage Model'!$D$42) -> 0.093059925 | P12: =(Y12*P$4-AB12*Inputs!$B$40)/AC12-('Voyage Model'!$D$42) -> 0.10845123 | Q12: =(Y12*Q$4-AB12*Inputs!$B$40)/AC12-('Voyage Model'!$D$42) -> 0.12384254 | R12: =(Y12*R$4-AB12*Inputs!$B$40)/AC12-('Voyage Model'!$D$42) -> 0.13923385 | S12: =(Y12*S$4-AB12*Inputs!$B$40)/AC12-('Voyage Model'!$D$42) -> 0.15462515 | T12: =(Y12*T$4-AB12*Inputs!$B$40)/AC12-('Voyage Model'!$D$42) -> 0.17001646 | U12: =(Y12*U$4-AB12*Inputs!$B$40)/AC12-('Voyage Model'!$D$42) -> 0.18540777 | X12: =A12*Inputs!$B$10*Inputs!$B$11 -> 6244560 | Y12: =X12*'Voyage Model'!$C$9 -> 362151.8 | Z12: =B12*1000*'Voyage Model'!$C$6*Inputs!$B$33 -> 20432932 | AA12: =Y12*Inputs!$B$34*Inputs!$B$35 -> 43458216 | AB12: =MIN(AA12,Z12)/Inputs!$B$33/1000 -> 508.2819 | AC12: =X12*(1-'Voyage Model'!$C$9) -> 5882408.2
A13: 100000 | B13: =Inputs!$B$15*(A13/Inputs!$B$9)^Inputs!$B$44 -> 18.272248 | C13: =IF(Y13=0,"n/a",('Voyage Model'!$D$42*AC13+AB13*Inputs!$B$40)/Y13) -> 0.95940074 | E13: =(Y13*E$4-AB13*Inputs!$B$40)/AC13-('Voyage Model'!$D$42) -> -0.059065725 | F13: =(Y13*F$4-AB13*Inputs!$B$40)/AC13-('Voyage Model'!$D$42) -> -0.043674418 | G13: =(Y13*G$4-AB13*Inputs!$B$40)/AC13-('Voyage Model'!$D$42) -> -0.028283111 | H13: =(Y13*H$4-AB13*Inputs!$B$40)/AC13-('Voyage Model'!$D$42) -> -0.012891804 | I13: =(Y13*I$4-AB13*Inputs!$B$40)/AC13-('Voyage Model'!$D$42) -> 0.0024995025 | J13: =(Y13*J$4-AB13*Inputs!$B$40)/AC13-('Voyage Model'!$D$42) -> 0.017890809 | K13: =(Y13*K$4-AB13*Inputs!$B$40)/AC13-('Voyage Model'!$D$42) -> 0.033282116 | L13: =(Y13*L$4-AB13*Inputs!$B$40)/AC13-('Voyage Model'!$D$42) -> 0.048673423 | M13: =(Y13*M$4-AB13*Inputs!$B$40)/AC13-('Voyage Model'!$D$42) -> 0.06406473 | N13: =(Y13*N$4-AB13*Inputs!$B$40)/AC13-('Voyage Model'!$D$42) -> 0.079456037 | O13: =(Y13*O$4-AB13*Inputs!$B$40)/AC13-('Voyage Model'!$D$42) -> 0.094847344 | P13: =(Y13*P$4-AB13*Inputs!$B$40)/AC13-('Voyage Model'!$D$42) -> 0.11023865 | Q13: =(Y13*Q$4-AB13*Inputs!$B$40)/AC13-('Voyage Model'!$D$42) -> 0.12562996 | R13: =(Y13*R$4-AB13*Inputs!$B$40)/AC13-('Voyage Model'!$D$42) -> 0.14102127 | S13: =(Y13*S$4-AB13*Inputs!$B$40)/AC13-('Voyage Model'!$D$42) -> 0.15641257 | T13: =(Y13*T$4-AB13*Inputs!$B$40)/AC13-('Voyage Model'!$D$42) -> 0.17180388 | U13: =(Y13*U$4-AB13*Inputs!$B$40)/AC13-('Voyage Model'!$D$42) -> 0.18719519 | X13: =A13*Inputs!$B$10*Inputs!$B$11 -> 6938400 | Y13: =X13*'Voyage Model'!$C$9 -> 402390.89 | Z13: =B13*1000*'Voyage Model'!$C$6*Inputs!$B$33 -> 21920525 | AA13: =Y13*Inputs!$B$34*Inputs!$B$35 -> 48286907 | AB13: =MIN(AA13,Z13)/Inputs!$B$33/1000 -> 545.28668 | AC13: =X13*(1-'Voyage Model'!$C$9) -> 6536009.1
A14: 110000 | B14: =Inputs!$B$15*(A14/Inputs!$B$9)^Inputs!$B$44 -> 19.471567 | C14: =IF(Y14=0,"n/a",('Voyage Model'!$D$42*AC14+AB14*Inputs!$B$40)/Y14) -> 0.9340005 | E14: =(Y14*E$4-AB14*Inputs!$B$40)/AC14-('Voyage Model'!$D$42) -> -0.057501954 | F14: =(Y14*F$4-AB14*Inputs!$B$40)/AC14-('Voyage Model'!$D$42) -> -0.042110647 | G14: =(Y14*G$4-AB14*Inputs!$B$40)/AC14-('Voyage Model'!$D$42) -> -0.02671934 | H14: =(Y14*H$4-AB14*Inputs!$B$40)/AC14-('Voyage Model'!$D$42) -> -0.011328033 | I14: =(Y14*I$4-AB14*Inputs!$B$40)/AC14-('Voyage Model'!$D$42) -> 0.0040632742 | J14: =(Y14*J$4-AB14*Inputs!$B$40)/AC14-('Voyage Model'!$D$42) -> 0.019454581 | K14: =(Y14*K$4-AB14*Inputs!$B$40)/AC14-('Voyage Model'!$D$42) -> 0.034845888 | L14: =(Y14*L$4-AB14*Inputs!$B$40)/AC14-('Voyage Model'!$D$42) -> 0.050237195 | M14: =(Y14*M$4-AB14*Inputs!$B$40)/AC14-('Voyage Model'!$D$42) -> 0.065628502 | N14: =(Y14*N$4-AB14*Inputs!$B$40)/AC14-('Voyage Model'!$D$42) -> 0.081019809 | O14: =(Y14*O$4-AB14*Inputs!$B$40)/AC14-('Voyage Model'!$D$42) -> 0.096411116 | P14: =(Y14*P$4-AB14*Inputs!$B$40)/AC14-('Voyage Model'!$D$42) -> 0.11180242 | Q14: =(Y14*Q$4-AB14*Inputs!$B$40)/AC14-('Voyage Model'!$D$42) -> 0.12719373 | R14: =(Y14*R$4-AB14*Inputs!$B$40)/AC14-('Voyage Model'!$D$42) -> 0.14258504 | S14: =(Y14*S$4-AB14*Inputs!$B$40)/AC14-('Voyage Model'!$D$42) -> 0.15797634 | T14: =(Y14*T$4-AB14*Inputs!$B$40)/AC14-('Voyage Model'!$D$42) -> 0.17336765 | U14: =(Y14*U$4-AB14*Inputs!$B$40)/AC14-('Voyage Model'!$D$42) -> 0.18875896 | X14: =A14*Inputs!$B$10*Inputs!$B$11 -> 7632240 | Y14: =X14*'Voyage Model'!$C$9 -> 442629.98 | Z14: =B14*1000*'Voyage Model'!$C$6*Inputs!$B$33 -> 23359302 | AA14: =Y14*Inputs!$B$34*Inputs!$B$35 -> 53115598 | AB14: =MIN(AA14,Z14)/Inputs!$B$33/1000 -> 581.07717 | AC14: =X14*(1-'Voyage Model'!$C$9) -> 7189610
A15: 120000 | B15: =Inputs!$B$15*(A15/Inputs!$B$9)^Inputs!$B$44 -> 20.635066 | C15: =IF(Y15=0,"n/a",('Voyage Model'!$D$42*AC15+AB15*Inputs!$B$40)/Y15) -> 0.9115054 | E15: =(Y15*E$4-AB15*Inputs!$B$40)/AC15-('Voyage Model'!$D$42) -> -0.056117038 | F15: =(Y15*F$4-AB15*Inputs!$B$40)/AC15-('Voyage Model'!$D$42) -> -0.040725731 | G15: =(Y15*G$4-AB15*Inputs!$B$40)/AC15-('Voyage Model'!$D$42) -> -0.025334424 | H15: =(Y15*H$4-AB15*Inputs!$B$40)/AC15-('Voyage Model'!$D$42) -> -0.0099431169 | I15: =(Y15*I$4-AB15*Inputs!$B$40)/AC15-('Voyage Model'!$D$42) -> 0.0054481901 | J15: =(Y15*J$4-AB15*Inputs!$B$40)/AC15-('Voyage Model'!$D$42) -> 0.020839497 | K15: =(Y15*K$4-AB15*Inputs!$B$40)/AC15-('Voyage Model'!$D$42) -> 0.036230804 | L15: =(Y15*L$4-AB15*Inputs!$B$40)/AC15-('Voyage Model'!$D$42) -> 0.051622111 | M15: =(Y15*M$4-AB15*Inputs!$B$40)/AC15-('Voyage Model'!$D$42) -> 0.067013418 | N15: =(Y15*N$4-AB15*Inputs!$B$40)/AC15-('Voyage Model'!$D$42) -> 0.082404725 | O15: =(Y15*O$4-AB15*Inputs!$B$40)/AC15-('Voyage Model'!$D$42) -> 0.097796032 | P15: =(Y15*P$4-AB15*Inputs!$B$40)/AC15-('Voyage Model'!$D$42) -> 0.11318734 | Q15: =(Y15*Q$4-AB15*Inputs!$B$40)/AC15-('Voyage Model'!$D$42) -> 0.12857865 | R15: =(Y15*R$4-AB15*Inputs!$B$40)/AC15-('Voyage Model'!$D$42) -> 0.14396995 | S15: =(Y15*S$4-AB15*Inputs!$B$40)/AC15-('Voyage Model'!$D$42) -> 0.15936126 | T15: =(Y15*T$4-AB15*Inputs!$B$40)/AC15-('Voyage Model'!$D$42) -> 0.17475257 | U15: =(Y15*U$4-AB15*Inputs!$B$40)/AC15-('Voyage Model'!$D$42) -> 0.19014387 | X15: =A15*Inputs!$B$10*Inputs!$B$11 -> 8326080 | Y15: =X15*'Voyage Model'!$C$9 -> 482869.07 | Z15: =B15*1000*'Voyage Model'!$C$6*Inputs!$B$33 -> 24755108 | AA15: =Y15*Inputs!$B$34*Inputs!$B$35 -> 57944288 | AB15: =MIN(AA15,Z15)/Inputs!$B$33/1000 -> 615.79872 | AC15: =X15*(1-'Voyage Model'!$C$9) -> 7843210.9
A16: 130000 | B16: =Inputs!$B$15*(A16/Inputs!$B$9)^Inputs!$B$44 -> 21.76668 | C16: =IF(Y16=0,"n/a",('Voyage Model'!$D$42*AC16+AB16*Inputs!$B$40)/Y16) -> 0.89137967 | E16: =(Y16*E$4-AB16*Inputs!$B$40)/AC16-('Voyage Model'!$D$42) -> -0.054877993 | F16: =(Y16*F$4-AB16*Inputs!$B$40)/AC16-('Voyage Model'!$D$42) -> -0.039486686 | G16: =(Y16*G$4-AB16*Inputs!$B$40)/AC16-('Voyage Model'!$D$42) -> -0.024095379 | H16: =(Y16*H$4-AB16*Inputs!$B$40)/AC16-('Voyage Model'!$D$42) -> -0.0087040718 | I16: =(Y16*I$4-AB16*Inputs!$B$40)/AC16-('Voyage Model'!$D$42) -> 0.0066872352 | J16: =(Y16*J$4-AB16*Inputs!$B$40)/AC16-('Voyage Model'!$D$42) -> 0.022078542 | K16: =(Y16*K$4-AB16*Inputs!$B$40)/AC16-('Voyage Model'!$D$42) -> 0.037469849 | L16: =(Y16*L$4-AB16*Inputs!$B$40)/AC16-('Voyage Model'!$D$42) -> 0.052861156 | M16: =(Y16*M$4-AB16*Inputs!$B$40)/AC16-('Voyage Model'!$D$42) -> 0.068252463 | N16: =(Y16*N$4-AB16*Inputs!$B$40)/AC16-('Voyage Model'!$D$42) -> 0.08364377 | O16: =(Y16*O$4-AB16*Inputs!$B$40)/AC16-('Voyage Model'!$D$42) -> 0.099035077 | P16: =(Y16*P$4-AB16*Inputs!$B$40)/AC16-('Voyage Model'!$D$42) -> 0.11442638 | Q16: =(Y16*Q$4-AB16*Inputs!$B$40)/AC16-('Voyage Model'!$D$42) -> 0.12981769 | R16: =(Y16*R$4-AB16*Inputs!$B$40)/AC16-('Voyage Model'!$D$42) -> 0.145209 | S16: =(Y16*S$4-AB16*Inputs!$B$40)/AC16-('Voyage Model'!$D$42) -> 0.1606003 | T16: =(Y16*T$4-AB16*Inputs!$B$40)/AC16-('Voyage Model'!$D$42) -> 0.17599161 | U16: =(Y16*U$4-AB16*Inputs!$B$40)/AC16-('Voyage Model'!$D$42) -> 0.19138292 | X16: =A16*Inputs!$B$10*Inputs!$B$11 -> 9019920 | Y16: =X16*'Voyage Model'!$C$9 -> 523108.16 | Z16: =B16*1000*'Voyage Model'!$C$6*Inputs!$B$33 -> 26112663 | AA16: =Y16*Inputs!$B$34*Inputs!$B$35 -> 62772979 | AB16: =MIN(AA16,Z16)/Inputs!$B$33/1000 -> 649.56872 | AC16: =X16*(1-'Voyage Model'!$C$9) -> 8496811.8
... A23: 200000 | B23: =Inputs!$B$15*(A23/Inputs!$B$9)^Inputs!$B$44 -> 29.012088 | C23: =IF(Y23=0,"n/a",('Voyage Model'!$D$42*AC23+AB23*Inputs!$B$40)/Y23) -> 0.79181393 | E23: =(Y23*E$4-AB23*Inputs!$B$40)/AC23-('Voyage Model'!$D$42) -> -0.048748205 | F23: =(Y23*F$4-AB23*Inputs!$B$40)/AC23-('Voyage Model'!$D$42) -> -0.033356898 | G23: =(Y23*G$4-AB23*Inputs!$B$40)/AC23-('Voyage Model'!$D$42) -> -0.017965591 | H23: =(Y23*H$4-AB23*Inputs!$B$40)/AC23-('Voyage Model'!$D$42) -> -0.002574284 | I23: =(Y23*I$4-AB23*Inputs!$B$40)/AC23-('Voyage Model'!$D$42) -> 0.012817023 | J23: =(Y23*J$4-AB23*Inputs!$B$40)/AC23-('Voyage Model'!$D$42) -> 0.02820833 | K23: =(Y23*K$4-AB23*Inputs!$B$40)/AC23-('Voyage Model'!$D$42) -> 0.043599637 | L23: =(Y23*L$4-AB23*Inputs!$B$40)/AC23-('Voyage Model'!$D$42) -> 0.058990944 | M23: =(Y23*M$4-AB23*Inputs!$B$40)/AC23-('Voyage Model'!$D$42) -> 0.074382251 | N23: =(Y23*N$4-AB23*Inputs!$B$40)/AC23-('Voyage Model'!$D$42) -> 0.089773558 | O23: =(Y23*O$4-AB23*Inputs!$B$40)/AC23-('Voyage Model'!$D$42) -> 0.10516486 | P23: =(Y23*P$4-AB23*Inputs!$B$40)/AC23-('Voyage Model'!$D$42) -> 0.12055617 | Q23: =(Y23*Q$4-AB23*Inputs!$B$40)/AC23-('Voyage Model'!$D$42) -> 0.13594748 | R23: =(Y23*R$4-AB23*Inputs!$B$40)/AC23-('Voyage Model'!$D$42) -> 0.15133879 | S23: =(Y23*S$4-AB23*Inputs!$B$40)/AC23-('Voyage Model'!$D$42) -> 0.16673009 | T23: =(Y23*T$4-AB23*Inputs!$B$40)/AC23-('Voyage Model'!$D$42) -> 0.1821214 | U23: =(Y23*U$4-AB23*Inputs!$B$40)/AC23-('Voyage Model'!$D$42) -> 0.19751271 | X23: =A23*Inputs!$B$10*Inputs!$B$11 -> 13876800 | Y23: =X23*'Voyage Model'!$C$9 -> 804781.78 | Z23: =B23*1000*'Voyage Model'!$C$6*Inputs!$B$33 -> 34804704 | AA23: =Y23*Inputs!$B$34*Inputs!$B$35 -> 96573814 | AB23: =MIN(AA23,Z23)/Inputs!$B$33/1000 -> 865.78866 | AC23: =X23*(1-'Voyage Model'!$C$9) -> 13072018
A25: Green = LH₂ cheaper. Red = NH₃ cheaper. White ≈ parity. Column C is the exact parity price per row (closed-form).
A26: The 40,000 m³ and 60,000... rows above land on exact 10,000 m³ steps; 160,000 m³ is included as a grid row too.
A27: NH₃ reference cost (active mode, current NH3 vessel/price): 'Voyage Model'!$D$42

Sheet NH3 Scenarios
A1: NH₃ Vessel Scenarios
A2: How many ammonia ships of each size equal one LH2 carrier at the current LH2 capacity/route? Speed, port time and BOR held at their Inputs values — only capacity varies here.
A4: NH₃ capacity (m³) | B4: Annual H₂-eq (ktpa/vessel) | C4: vs 1 LH₂ ship | D4: NH₃ ships per LH₂ ship
A5: 24000 | B5: =((A5*Inputs!$B$19*Inputs!$B$20)*(365/(2*(Inputs!$B$6/Inputs!$B$22/24)+2*Inputs!$B$23)*Inputs!$B$30)/Inputs!$B$32)/1000000 -> 12.2496 | C5: =(B5*1000000)/'Voyage Model'!$C$14 -> 0.22173657 | D5: ='Voyage Model'!$C$14/(B5*1000000) -> 4.5098559 | F5: ='Voyage Model'!$C$15 -> 55.24393
A6: 40000 | B6: =((A6*Inputs!$B$19*Inputs!$B$20)*(365/(2*(Inputs!$B$6/Inputs!$B$22/24)+2*Inputs!$B$23)*Inputs!$B$30)/Inputs!$B$32)/1000000 -> 20.416 | C6: =(B6*1000000)/'Voyage Model'!$C$14 -> 0.36956096 | D6: ='Voyage Model'!$C$14/(B6*1000000) -> 2.7059136 | F6: ='Voyage Model'!$C$15 -> 55.24393
A7: 60000 | B7: =((A7*Inputs!$B$19*Inputs!$B$20)*(365/(2*(Inputs!$B$6/Inputs!$B$22/24)+2*Inputs!$B$23)*Inputs!$B$30)/Inputs!$B$32)/1000000 -> 30.624 | C7: =(B7*1000000)/'Voyage Model'!$C$14 -> 0.55434143 | D7: ='Voyage Model'!$C$14/(B7*1000000) -> 1.8039424 | F7: ='Voyage Model'!$C$15 -> 55.24393
